Workbook

Sheet Cover Page

Sheet Assumption & Definition
A1: Mo Ambulance
A2: A | B2: DEFINITION OF REVENUE SOURCE | C2: DESCRIPTIONS
A3: 1 | B3: B2B | C3: Hospital, Industry, Corporates
A4: 2 | B4: HAMS | C4: Hospital Ambulance Management System
A5: 3 | B5: MHU | C5: Mobile Health Unit
A6: 4 | B6: AMTeK & AMTeK-V | C6: Oxygen Sylinder Sensor, Breath Analyser, GPS, web Camera, E-log Book, Dashboard & Vital Parameter device (ECG, Oxygen Saturation, PR, Temp, RR, BP)
A7: 6 | B7: ATOMS | C7: Ambulance Traffic Organisation & Management System for Urban and Smart City
A8: 6 | B8: KIOSK (PRE PAID) | C8: Pre Paid KISOK for Ambulance Management at Multispeciality Hospital
A9: 7 | B9: INDUSTRY | C9: Colloboration Approach in Industry and Corporate for Ambulance 24X7 Support Service
A10: 8 | B10: WHITE LABELLING (B2B) | C10: Labelling of all app (B2C/DRIVER/HAMS) IN HOSPITAL NAME
A13: B | B13: ASSUMPTIONS & CLARIFICATIONS | C13: DESCRIPTIONS
A14: 1 | B14: PRE PAID KISOK AMBULANCE MODEL | C14: Mo Ambulance has started the discussion with Odisha Govt. to introduce this Model in Major Hospital with >500 bedded (Medical College & Hospital)
A15: 2 | B15: HAMS (Hospital Ambulance Management System | C15: Mo Ambulance has Started the Implementation of Ambulance Support through Integration of tech Application with different Customize Model for Hospital
A16: 3 | B16: AMBULANCE OXYGEN SENSOR (B2B) | C16: Mo Ambulance has planned to integrate in all Ambulance of Govt to Monitor the Oxygen Level
A17: 4 | B17: Govt. Level Policy Level | C17: Mo Ambulance will have proposal to work with Govt. at the Policy Level implementation on Quality Assurance of the Private ambulance
A18: 5 | B18: Smart City Implementation (ATOMS) | C18: Mo Ambulance has planned to introduce the smart city Ambulance Surveillance Model in Bhubaneswar Smart City to avoid the Crowd
A19: 6 | B19: IOT | C19: Mo Ambulance is in process to scale up the Bihar Project to State wise
A20: 7 | B20: 5G Mo Ambulance | C20: Reformation of Existing Ambulance to 5G Ambulance with Low Cost
A21: 8 | B21: Policy Level Implementation of Factory Act 1948 | C21: To implement the inhouse Ambulance as per Factory Act 1948
A22: 9 | B22: INDUSTRY | C22: Mo Ambulance has submitted the Proposal to TATA, JSW, PPL for Smart Ambulance Management Project
A23: 10 | B23: WHITE LABELLING (B2B) | C23: Mo Ambulance is in Process of Developing the White Labelling Application for Chain of Hospital as Emergency Medical Service App. which includes the Patient App, Ambulance Driver app, and Hospital App.
A24: 11 | B24: Insurance Support through B2C App. | C24: Mo Ambulance is in discussion with Insurance Company to support insurance for the Ambulance Ride Cost and also approval of Patient Treatment Cost before arrival at the hospital
A25: 12 | B25: Mobile Health Unit (MHU) | C25: MHU support to the Onboarded Hospital for Patient footfall support and revenue generation of both
... A28: 15 | B28: Rental Ambulance | C28: As we have the aggregator of Ambulance , we are getting Proposal for Rental Ambulance

Sheet Revenue
B2: SUMMARY OF CURRENT FINANCIAL STATUS & PROJECTIONS
B4: Years | C4: Sources of Revenue | K4: TOTAL REVENUE TO MO AMBULANCE (RS) | L4: EXPENDITURE | M4: EBIDTA | N4: EBIDTA (%)
C5: Agregator Ride | D5: Hospital Partnership Model -HAMS (B2B) | E5: Industry (B2B) | F5: MHU | G5: AMBULANCE OXYGEN SENSOR (B2B) | H5: IOT(B2B): ATOMS | I5: PRE PAID KISOK @900 PER MONTH PER KIOSK | J5: WHITE LABELLING (B2B)
B7: 2021-22 | C7: ='2021-22'!O5 -> 3167192 | D7: ='2021-22'!O8 -> 33050 | K7: =C7+D7 -> 3200242 | L7: 6466000 | M7: =K7-L7 -> -3265758 | N7: =M7/K7 -> -1.0204722
B8: 2022-23 | C8: 9449000 | D8: 76000 | E8: 0 | F8: 39000 | G8: 0 | H8: 1290000 | I8: 0 | J8: 0 | K8: =C8+D8+F8+E8+G8+H8+I8+J8 -> 10854000 | L8: 13656000 | M8: =K8-L8 -> -2802000 | N8: =M8/K8 -> -0.25815368
B9: 2023-24 | C9: ='2023-24'!O7 -> 2700000 | D9: ='2023-24'!O12 -> 27450000 | E9: ='2023-24'!O16 -> 600000 | F9: ='2023-24'!O14 -> 360000 | G9: ='2023-24'!O21 -> 7000000 | H9: ='2023-24'!O23 -> 1720000 | I9: ='2023-24'!O25 -> 0 | J9: ='2023-24'!O30 -> 400000 | K9: =C9+D9+E9+F9+G9+H9+I9+J9 -> 40230000 | L9: =Expenses!H6 -> 38218500 | M9: =K9-L9 -> 2011500 | N9: =M9/K9 -> 0.05
B10: 2024-25 | C10: ='2024-25'!O12 -> 14400000 | D10: ='2024-25'!O17 -> 103800000 | E10: ='2024-25'!O21 -> 6000000 | F10: ='2024-25'!O19 -> 2160000 | G10: ='2024-25'!O27 -> 35000000 | H10: ='2024-25'!O29 -> 25800000 | I10: ='2024-25'!O31 -> 25920000 | J10: ='2024-25'!O38 -> 1800000 | K10: =J10+I10+H10+G10+F10+E10+D10+C10 -> 214880000 | L10: =Expenses!J6 -> 186945600 | M10: =K10-L10 -> 27934400 | N10: =M10/K10 -> 0.13
B11: 2025-26 | C11: ='2025-26'!O15 -> 72000000 | D11: ='2025-26'!O25 -> 291150000 | E11: ='2025-26'!O34 -> 20160000 | F11: ='2025-26'!O30 -> 10800000 | G11: ='2025-26'!O43 -> 84000000 | H11: ='2025-26'!O45 -> 103200000 | I11: ='2025-26'!O52 -> 116640000 | J11: ='2025-26'!O62 -> 2400000 | K11: =J11+I11+H11+G11+F11+E11+D11+C11 -> 700350000 | L11: =Expenses!L6 -> 588294000 | M11: =K11-L11 -> 112056000 | N11: =M11/K11 -> 0.16

Sheet Expenses
A3: Detail Expences Projection with respect Business Model from 2023-2026
B4: Expences Head | C4: FY 21-22 | E4: FY 22-23 | G4: FY 23-24 | I4: FY 24-25 | K4: FY 25 - 26 | O4: FY 23 - 24
C5: Income | D5: Expenditure | E5: Income | F5: Expenditure | G5: Income | H5: Expenditure | I5: Income | J5: Expenditure | K5: Income | L5: Expenditure
C6: ='2021-22'!O9 -> 3200242 | D6: 6466000 | E6: ='2022-23'!O15 -> 10854000 | F6: 13656000 | G6: ='2023-24'!O32 -> 40230000 | H6: 38218500 | I6: ='2024-25'!O39 -> 214880000 | J6: 186945600 | K6: ='2025-26'!O63 -> 700350000 | L6: 588294000
B8: Employee Cost | D8: 2149000 | F8: 3178000 | H8: 10057500 | J8: 42976000 | L8: 140070000
B9: Sales & Marketing Cost | D9: 153000 | F9: 708000 | H9: 4023000 | J9: 21488000 | L9: 70035000
B10: Hospital & Aggregator Cost | D10: 2900000 | F10: 8409000 | H10: 18103500 | J10: 85952000 | L10: 259129500
B11: IT , IOT & Server Cost | D11: 468000 | F11: 50000 | H11: 2011500 | J11: 16116000 | L11: 52526250
B12: R&D , IP, Publication Cost | D12: 145000 | F12: 60000 | H12: 1005750 | J12: 4297600 | L12: 14007000
B13: Administration Cost | D13: 550000 | F13: 1194000 | H13: 2011500 | J13: 5372000 | L13: 17508750
B14: Mislaneous | D14: 101000 | F14: 57000 | H14: 1005750 | J14: 10744000 | L14: 35017500
B17: Profit/Loss | D17: =C6-D6 -> -3265758 | F17: =E6-F6 -> -2802000 | H17: =G6-H6 -> 2011500 | J17: =I6-J6 -> 27934400 | L17: =K6-L6 -> 112056000
B18: EBITDA% | D18: =D17/C6% -> -102.04722 | F18: =F17/E6% -> -25.815368 | H18: =H17/G6% -> 5 | J18: =J17/I6% -> 13 | L18: =L17/K6% -> 16

Sheet 2021-22
A1: FY 2021-22
D2: Revenue Sources
B3: Revenue Sources | C3: States / Cities | D3: Hospitals/KISOK | E3: Number of Ambulance Onboard | F3: Industry | G3: MHU | H3: IOT | I3: HAMS COST PER MONTH | J3: Cost per Ride | K3: Cost per Industry | L3: Cost per MHU Screen | M3: Cost per IOT (Oxygensensor/other) | N3: WHITE LABELLING | O3: Oerall Revenue
A4: 1 | B4: RIDES (B2C)
C5: Odisha | E5: 200 | J5: 1000 | O5: 3167192
A7: 2 | B7: HAMS (B2B)
C8: Odisha | E8: 13 | J8: 1000 | O8: 33050
N9: Total | O9: =SUM(O5:O8) -> 3200242

Sheet 2022-23
A1: FY 2022-23
D2: Revenue Sources in Number
B3: Revenue Sources | C3: States / Cities | D3: Hospitals/KISOK | E3: Number of Ambulance Onboard | F3: Industry | G3: MHU | H3: IOT | I3: HAMS COST PER MONTH | J3: Cost per Ride | K3: Cost per Industry | L3: Cost per MHU Screening | M3: Cost per IOT (Oxygensensor/other) | N3: WHITE LABELLING | O3: Oerall Revenue
A5: 1 | B5: RIDE (B2C) | C5: Odisha | E5: 500 | J5: 1000 | O5: 9449000
O6: =O5 -> 9449000
A7: 2 | B7: HAMS(B2B) | C7: Odisha | D7: 44 | I7: 1000 | O7: 76000
O8: =O7 -> 76000
A9: 3 | B9: MHU (B2B2C)
C10: Odisha | G10: 1 | L10: 300 | O10: 39000
O11: =O10 -> 39000
A12: 4 | B12: IOT (B2B) | C12: Odisha
C13: Bihar | H13: 11 | M13: 1290000 | O13: 1290000
O14: =O13 -> 1290000
N15: Total | O15: =O14+O11+O8+O6 -> 10854000

Sheet 2023-24
A1: FY 2023-24
D2: Revenue Sources in Number
B3: Revenue Sources | C3: States / Cities | D3: Hospitals/KISOK/White Labelling | E3: Number of Ambulance Onboard | F3: Industry | G3: MHU | H3: ATOMS (IOT) | I3: HAMS COST PER MONTH | J3: Cost per Ride | K3: Cost per Industry | L3: Cost per MHU Screening | M3: Cost per IOT (Oxygen sensor/other) | N3: WHITE LABELLING UNIT COST | O3: Overall Revenue
A5: 1 | B5: RIDE (B2C) | C5: Odisha | E5: 450 | J5: 1200 | O5: =(E5*2/100)*J5*25*10 -> 2700000
O6: =(E6*2/100)*J6*25*3 -> 0
O7: =SUM(O5:O6) -> 2700000
A8: 2 | B8: HAMS (B2B) | C8: Odisha | D8: 10 | I8: 450000 | O8: =I8*D8*6 -> 27000000
C9: Odisha | D9: 50 | I9: 1500 | O9: =I9*D9*6 -> 450000
C10: West Bengal | D10: 0 | I10: 500000 | O10: =I10*D10*3 -> 0
C11: Jharkhand | D11: 0 | I11: 500000 | O11: =I11*D11*3 -> 0
O12: =SUM(O8:O11) -> 27450000
A13: 3 | B13: MHU | C13: Odisha | G13: 1 | L13: 300 | O13: =L13*G13*200*6 -> 360000
O14: =SUM(O13:O13) -> 360000
A15: 4 | B15: INDUSTRY (B2B) | C15: Odisha | F15: 2 | K15: 100000 | O15: =K15*F15*3 -> 600000
O16: =SUM(O15:O15) -> 600000
A17: 5 | B17: AMTeK & AMTeK-V | C17: Odisha | H17: 100 | M17: 70000 | O17: =M17*H17 -> 7000000
C18: Bihar | H18: 0 | M18: 70000 | O18: =M18*H18 -> 0
C19: Chhattisgarh | H19: 0 | M19: 70000 | O19: =M19*H19 -> 0
C20: Jharkhand | H20: 0 | M20: 70000 | O20: =M20*H20 -> 0
O21: =SUM(O17:O20) -> 7000000
A22: 6 | B22: IOT(B2B): ATOMS | C22: Odisha (100junction/City) | H22: 2 | M22: 430000 | O22: =M22*H22*2 -> 1720000
O23: =SUM(O22:O22) -> 1720000
A24: 7 | B24: PRE PAID KISOK @900 PER MONTH PER KIOSK | C24: Orissa | D24: 0 | J24: 1200 | O24: =J24*D24*900*2 -> 0
O25: =SUM(O24:O24) -> 0
A26: 8 | B26: WHITE LABELLING (B2B) | C26: Odisha | D26: 2 | N26: 200000 | O26: =N26*D26 -> 400000
C27: Bihar | D27: 0
C28: Chhattisgarh | D28: 0
C29: Jharkhand | D29: 0
O30: =SUM(O26:O29) -> 400000
N32: TOTAL | O32: =O30+O25+O23+O21+O16+O14+O12+O7 -> 40230000

Sheet 2024-25
A1: FY 2024-25
D3: Revenue Sources in Number
B5: Revenue Sources | C5: States / Cities | D5: Hospitals/KISOK | E5: Number of Ambulance Onboard | F5: Industry | G5: MHU | H5: IOT | I5: HAMS COST PER MONTH | J5: Cost per Ride | K5: Cost per Industry | L5: Cost perWhite Labelling | M5: Cost per MHU Screening | N5: Cost per IOT (Oxygen sensor/other) | O5: Overall Revenue
A7: 1 | B7: RIDE (B2C) | C7: Odisha | E7: 1000 | J7: 1200 | O7: =(E7*2/100)*J7*25*12 -> 7200000
C8: Bihar | E8: 250 | J8: 1200 | O8: =(E8*2/100)*J8*25*12 -> 1800000
C9: Chhattisgarh | E9: 250 | J9: 1200 | O9: =(E9*2/100)*J9*25*12 -> 1800000
C10: West Bengal | E10: 250 | J10: 1200 | O10: =(E10*2/100)*J10*25*12 -> 1800000
C11: Jharkand | E11: 250 | J11: 1200 | O11: =(E11*2/100)*J11*25*12 -> 1800000
O12: =SUM(O7:O11) -> 14400000
A13: 2 | B13: HAMS(B2B) | C13: Odisha | D13: 15 | I13: 450000 | O13: =I13*D13*12 -> 81000000
C14: Odisha | D14: 100 | I14: 1500 | O14: =I14*D14*12 -> 1800000
C15: Jharkhand | D15: 2 | I15: 450000 | O15: =I15*D15*10 -> 9000000
C16: West Bengal | D16: 2 | I16: 500000 | O16: =I16*D16*12 -> 12000000
O17: =SUM(O13:O16) -> 103800000
A18: 3 | B18: MHU (B2B2C) | C18: Odisha | G18: 2 | M18: 300 | O18: =M18*G18*300*12 -> 2160000
O19: =SUM(O18:O18) -> 2160000
A20: 4 | B20: INDUSTRY (B2B) | C20: Odisha | F20: 5 | K20: 100000 | O20: =K20*F20*12 -> 6000000
O21: =SUM(O20:O20) -> 6000000
A22: 5 | B22: AMTeK & AMTeK-V | C22: Odisha | H22: 300 | N22: 70000 | O22: =N22*H22 -> 21000000
C23: Bihar | H23: 50 | N23: 70000 | O23: =N23*H23 -> 3500000
C24: Chhattisgarh | H24: 50 | N24: 70000 | O24: =N24*H24 -> 3500000
C25: Jharkhand | H25: 50 | N25: 70000 | O25: =N25*H25 -> 3500000
C26: West Bengal | H26: 50 | N26: 70000 | O26: =N26*H26 -> 3500000
O27: =SUM(O22:O26) -> 35000000
A28: 6 | B28: IOT(B2B): ATOMS | C28: India(100junction/City) | H28: 5 | N28: 430000 | O28: =N28*H28*12 -> 25800000
O29: =SUM(O28:O28) -> 25800000
A30: 7 | B30: PRE PAID KISOK @900 PER MONTH PER KIOSK | C30: Odisha | D30: 2 | J30: 1200 | O30: =J30*D30*900*12 -> 25920000
O31: =SUM(O30:O30) -> 25920000
A32: 8 | B32: WHITE LABELLING (B2B) | C32: Odisha | D32: 2 | L32: 200000 | O32: =L32*D32 -> 400000
C33: Bihar | D33: 0 | L33: 200000 | O33: =L33*D33 -> 0
C34: Chhattisgarh | D34: 0 | L34: 200000 | O34: =L34*D34 -> 0
C35: Jharkhand | D35: 0 | L35: 200000 | O35: =L35*D35 -> 0
C36: Bangalore | D36: 0 | L36: 200000 | O36: =L36*D36 -> 0
C37: West Bengal | D37: 0 | L37: 200000 | O37: =L37*D37 -> 0
O38: 1800000
N39: Total | O39: =O38+O31+O29+O27+O21+O19+O17+O12 -> 214880000

Sheet 2025-26
A1: FY 2025-26
D4: Revenue Sources in Number
B5: Revenue Sources | C5: States / Cities | D5: Hospitals/KISOK/API | E5: Ambulance Provider | F5: Industry | G5: MHU | H5: IOT | I5: HAMS COST PER MONTH | J5: Cost per Ride | K5: Cost per Industry | L5: Cost per White Labelling | M5: Cost per MHU Screening | N5: Cost per IOT (Oxygensensor/other/ATOMS) | O5: Oerall Revenue
A7: 1 | B7: RIDE (B2C) | C7: Odisha | E7: 1500 | J7: 1200 | O7: =(E7*4/100)*J7*25*12 -> 21600000
C8: Bihar | E8: 500 | J8: 1200 | O8: =(E8*4/100)*J8*25*12 -> 7200000
C9: Chattisgarh | E9: 500 | J9: 1200 | O9: =(E9*4/100)*J9*25*12 -> 7200000
C10: West Bengal | E10: 500 | J10: 1200 | O10: =(E10*4/100)*J10*25*12 -> 7200000
C11: Jharkand | E11: 500 | J11: 1200 | O11: =(E11*4/100)*J11*25*12 -> 7200000
C12: Bangalore | E12: 500 | J12: 1200 | O12: =(E12*4/100)*J12*25*12 -> 7200000
C13: Hyderabad | E13: 500 | J13: 1200 | O13: =(E13*4/100)*J13*25*12 -> 7200000
C14: Delhi | E14: 500 | J14: 1200 | O14: =(E14*4/100)*J14*25*12 -> 7200000
O15: =SUM(O7:O14) -> 72000000
A16: 3 | B16: HAMS(B2B) | C16: Odisha | D16: 20 | I16: 500000 | O16: =I16*D16*12 -> 120000000
C17: Odisha | D17: 150 | I17: 2500 | O17: =D17*I17*12 -> 4500000
C18: Bihar | D18: 5 | I18: 500000 | O18: =I18*D18*12 -> 30000000
C19: Jharkand | D19: 5 | I19: 500000 | O19: =I19*D19*12 -> 30000000
C20: West Bengal | D20: 5 | I20: 2500 | O20: =I20*D20*12 -> 150000
C21: Bangalore | D21: 50 | I21: 2500 | O21: =I21*D21*12 -> 1500000
C22: Bangalore | D22: 5 | I22: 500000 | O22: =I22*D22*12 -> 30000000
C23: Hyderabad | D23: 5 | I23: 500000 | O23: =I23*D23*12 -> 30000000
C24: Delhi | D24: 5 | I24: 750000 | O24: =I24*D24*12 -> 45000000
O25: =SUM(O16:O24) -> 291150000
A26: 4 | B26: MHU (B2B2C) | C26: Odisha | G26: 10 | M26: 300 | O26: =M26*G26*12*300 -> 10800000
C27: Bihar | G27: 0 | M27: 300 | O27: =M27*G27*12*300 -> 0
C28: Jharkand | G28: 0 | M28: 300 | O28: =M28*G28*12*300 -> 0
C29: West Bengal | G29: 0 | M29: 300 | O29: =M29*G29*12*300 -> 0
O30: =SUM(O26:O29) -> 10800000
A31: 5 | B31: INDUSTRY (B2B) | C31: Odisha | F31: 10 | K31: 120000 | O31: =K31*F31*12 -> 14400000
C32: Chattisgarh | F32: 2 | K32: 120000 | O32: =K32*F32*12 -> 2880000
C33: Jharkand | F33: 2 | K33: 120000 | O33: =K33*F33*12 -> 2880000
O34: =SUM(O31:O33) -> 20160000
A35: 6 | B35: AMTeK & AMTeK-V | C35: Odisha | H35: 500 | N35: 70000 | O35: =N35*H35 -> 35000000
C36: Bihar | H36: 100 | N36: 70000 | O36: =N36*H36 -> 7000000
C37: Chattisgarh | H37: 100 | N37: 70000 | O37: =N37*H37 -> 7000000
C38: Jharkand | H38: 100 | N38: 70000 | O38: =N38*H38 -> 7000000
C39: West Bengal | H39: 100 | N39: 70000 | O39: =N39*H39 -> 7000000
C40: Bangalore | H40: 100 | N40: 70000 | O40: =N40*H40 -> 7000000
C41: Hyderabad | H41: 100 | N41: 70000 | O41: =N41*H41 -> 7000000
C42: Delhi | H42: 100 | N42: 70000 | O42: =N42*H42 -> 7000000
O43: =SUM(O35:O42) -> 84000000
...
